<?xml version="1.0" encoding="utf-8"?>
<!-- This URDF was automatically created by SolidWorks to URDF Exporter! Originally created by Stephen Brawner (brawner@gmail.com) 
     Commit Version: 1.6.0-4-g7f85cfe  Build Version: 1.6.7995.38578
     For more information, please see http://wiki.ros.org/sw_urdf_exporter -->
<robot
  name="robot_V26">
  <link
    name="base_link">
    <inertial>
      <origin
        xyz="0.000433147072937283 -0.0560104420122413 0.235023220634512"
        rpy="0 0 0" />
      <mass
        value="186.068426983297" />
      <inertia
        ixx="5.13366744953187"
        ixy="4.82885339620413E-08"
        ixz="-2.48383948380018E-09"
        iyy="9.61398925705965"
        iyz="0.0555472265211471"
        izz="8.42705967760061" />
    </inertial>
    <visual>
      <origin
        xyz="0 0 0"
        rpy="0 0 0" />
      <geometry>
        <mesh
          filename="../meshes/base_link.STL" />
      </geometry>
      <material
        name="">
        <color
          rgba="0.6 0.6 0.6 1" />
      </material>
    </visual>
    <collision>
      <origin
        xyz="0 0 0"
        rpy="0 0 0" />
      <geometry>
        <mesh
          filename="../meshes/base_link.STL" />
      </geometry>
    </collision>
  </link>
  <link
    name="platform_link">
    <inertial>
      <origin
        xyz="0.00621557288384057 0.0303445183415779 -0.183382568462776"
        rpy="0 0 0" />
      <mass
        value="6.07294405347568" />
      <inertia
        ixx="0.0337898340637685"
        ixy="-0.00102088842956734"
        ixz="-7.64193248724239E-06"
        iyy="0.0339585958829543"
        iyz="-5.04855556084014E-05"
        izz="0.0128636661576432" />
    </inertial>
    <visual>
      <origin
        xyz="0 0 0"
        rpy="0 0 0" />
      <geometry>
        <mesh
          filename="../meshes/platform_link.STL" />
      </geometry>
      <material
        name="">
        <color
          rgba="0.898039215686275 0.917647058823529 0.929411764705882 1" />
      </material>
    </visual>
    <collision>
      <origin
        xyz="0 0 0"
        rpy="0 0 0" />
      <geometry>
        <mesh
          filename="../meshes/platform_link.STL" />
      </geometry>
    </collision>
  </link>
  <joint
    name="joint_platform_D1"
    type="revolute">
    <origin
      xyz="0 0 0"
      rpy="0 0 0" />
    <parent
      link="base_link" />
    <child
      link="platform_link" />
    <axis
      xyz="0 0 -1" />
    <limit
      lower="-3.14"
      upper="3.14"
      effort="100"
      velocity="50" />
  </joint>
  <link
    name="Link_A1">
    <inertial>
      <origin
        xyz="0.0169308367894223 0.0125928013215484 0.0768128774242119"
        rpy="0 0 0" />
      <mass
        value="0.593525762282562" />
      <inertia
        ixx="0.001211740353914"
        ixy="-4.04510751675718E-05"
        ixz="-0.000169403894082202"
        iyy="0.00123597531032555"
        iyz="-0.000126111277061559"
        izz="0.000561310092473764" />
    </inertial>
    <visual>
      <origin
        xyz="0 0 0"
        rpy="0 0 0" />
      <geometry>
        <mesh
          filename="../meshes/Link_A1.STL" />
      </geometry>
      <material
        name="">
        <color
          rgba="1 1 1 1" />
      </material>
    </visual>
    <collision>
      <origin
        xyz="0 0 0"
        rpy="0 0 0" />
      <geometry>
        <mesh
          filename="../meshes/Link_A1.STL" />
      </geometry>
    </collision>
  </link>
  <joint
    name="joint_platform_A1"
    type="revolute">
    <origin
      xyz="0.156472683129336 0.142433967655858 -0.227311716711955"
      rpy="-1.57079632679501 0 -0.826733214100753" />
    <parent
      link="platform_link" />
    <child
      link="Link_A1" />
    <axis
      xyz="0 0 1" />
    <limit
      lower="-3.14"
      upper="3.14"
      effort="100"
      velocity="50" />
  </joint>
  <link
    name="Link_A2">
    <inertial>
      <origin
        xyz="-0.0126344741529678 -0.151722416547969 0.0226638905008693"
        rpy="0 0 0" />
      <mass
        value="0.86418121779446" />
      <inertia
        ixx="0.00204291602200734"
        ixy="-0.000117497066496082"
        ixz="3.49972875797524E-05"
        iyy="0.00064232321003002"
        iyz="0.000420166412207833"
        izz="0.00195279780759874" />
    </inertial>
    <visual>
      <origin
        xyz="0 0 0"
        rpy="0 0 0" />
      <geometry>
        <mesh
          filename="../meshes/Link_A2.STL" />
      </geometry>
      <material
        name="">
        <color
          rgba="1 1 1 1" />
      </material>
    </visual>
    <collision>
      <origin
        xyz="0 0 0"
        rpy="0 0 0" />
      <geometry>
        <mesh
          filename="../meshes/Link_A2.STL" />
      </geometry>
    </collision>
  </link>
  <joint
    name="joint_platform_A2"
    type="revolute">
    <origin
      xyz="-0.0132108472999706 -0.00983204731723247 0.101999999998849"
      rpy="-1.5707963267949 -1.06818707313174 -0.930882582622158" />
    <parent
      link="Link_A1" />
    <child
      link="Link_A2" />
    <axis
      xyz="0 0 1" />
    <limit
      lower="-2.26"
      upper="2.26"
      effort="100"
      velocity="50" />
  </joint>
  <link
    name="Link_A3">
    <inertial>
      <origin
        xyz="0.0578270540391275 -0.0144992247222056 0.00266652645528004"
        rpy="0 0 0" />
      <mass
        value="0.289645631718229" />
      <inertia
        ixx="0.000184905971778833"
        ixy="0.000113389606191271"
        ixz="-0.000140277058410494"
        iyy="0.000608954988576286"
        iyz="3.51374387511307E-05"
        izz="0.000614182812194689" />
    </inertial>
    <visual>
      <origin
        xyz="0 0 0"
        rpy="0 0 0" />
      <geometry>
        <mesh
          filename="../meshes/Link_A3.STL" />
      </geometry>
      <material
        name="">
        <color
          rgba="1 1 1 1" />
      </material>
    </visual>
    <collision>
      <origin
        xyz="0 0 0"
        rpy="0 0 0" />
      <geometry>
        <mesh
          filename="../meshes/Link_A3.STL" />
      </geometry>
    </collision>
  </link>
  <joint
    name="joint_platform_A3"
    type="revolute">
    <origin
      xyz="-0.0212703972736464 -0.255104561293881 0.00352514725879639"
      rpy="0 0 0" />
    <parent
      link="Link_A2" />
    <child
      link="Link_A3" />
    <axis
      xyz="0 0 1" />
    <limit
      lower="-2.26"
      upper="2.26"
      effort="100"
      velocity="50" />
  </joint>
  <link
    name="Link_A4">
    <inertial>
      <origin
        xyz="0.0168960078739982 -0.00633304042254657 -0.0599615142706841"
        rpy="0 0 0" />
      <mass
        value="0.239433776203735" />
      <inertia
        ixx="0.000265607042244076"
        ixy="7.64305472317407E-06"
        ixz="4.14131928527047E-05"
        iyy="0.000283077938628801"
        iyz="-1.55624790065709E-05"
        izz="0.000119899347836856" />
    </inertial>
    <visual>
      <origin
        xyz="0 0 0"
        rpy="0 0 0" />
      <geometry>
        <mesh
          filename="../meshes/Link_A4.STL" />
      </geometry>
      <material
        name="">
        <color
          rgba="1 1 1 1" />
      </material>
    </visual>
    <collision>
      <origin
        xyz="0 0 0"
        rpy="0 0 0" />
      <geometry>
        <mesh
          filename="../meshes/Link_A4.STL" />
      </geometry>
    </collision>
  </link>
  <joint
    name="joint_platform_A4"
    type="revolute">
    <origin
      xyz="0.124662762966528 -0.0312689999385135 0.013235949944407"
      rpy="-1.5707963267949 -1.21130110529 1.32513220794321" />
    <parent
      link="Link_A3" />
    <child
      link="Link_A4" />
    <axis
      xyz="0 0 -1" />
    <limit
      lower="-3.14"
      upper="3.14"
      effort="100"
      velocity="50" />
  </joint>
  <link
    name="Link_A5">
    <inertial>
      <origin
        xyz="0.038009420996225 0.0456440435563882 0.00506811024883674"
        rpy="0 0 0" />
      <mass
        value="0.21879390742709" />
      <inertia
        ixx="0.000249967652296182"
        ixy="-0.000120769330574946"
        ixz="-5.00570636284899E-05"
        iyy="0.000205482026171739"
        iyz="-6.01294716590356E-05"
        izz="0.000334465809435568" />
    </inertial>
    <visual>
      <origin
        xyz="0 0 0"
        rpy="0 0 0" />
      <geometry>
        <mesh
          filename="../meshes/Link_A5.STL" />
      </geometry>
      <material
        name="">
        <color
          rgba="1 1 1 1" />
      </material>
    </visual>
    <collision>
      <origin
        xyz="0 0 0"
        rpy="0 0 0" />
      <geometry>
        <mesh
          filename="../meshes/Link_A5.STL" />
      </geometry>
    </collision>
  </link>
  <joint
    name="joint_platform_A5"
    type="revolute">
    <origin
      xyz="-0.0113606247812901 0.0042683371510126 -0.0814999999999998"
      rpy="1.5707963267949 1.32513220794321 1.21130110529" />
    <parent
      link="Link_A4" />
    <child
      link="Link_A5" />
    <axis
      xyz="0 0 1" />
    <limit
      lower="-2.2"
      upper="2.2"
      effort="100"
      velocity="50" />
  </joint>
  <link
    name="Link_A6">
    <inertial>
      <origin
        xyz="0.0103201473783717 0.0231563190196556 0.0565997915426926"
        rpy="0 0 0" />
      <mass
        value="0.451431232657582" />
      <inertia
        ixx="0.00022927173803935"
        ixy="-4.51808436026412E-05"
        ixz="-4.22975637695025E-09"
        iyy="0.000147938161669035"
        iyz="-3.34078039209366E-08"
        izz="0.000355045117472867" />
    </inertial>
    <visual>
      <origin
        xyz="0 0 0"
        rpy="0 0 0" />
      <geometry>
        <mesh
          filename="../meshes/Link_A6.STL" />
      </geometry>
      <material
        name="">
        <color
          rgba="1 1 1 1" />
      </material>
    </visual>
    <collision>
      <origin
        xyz="0 0 0"
        rpy="0 0 0" />
      <geometry>
        <mesh
          filename="../meshes/Link_A6.STL" />
      </geometry>
    </collision>
  </link>
  <joint
    name="joint_platform_A6"
    type="revolute">
    <origin
      xyz="0.0736102642149934 0.0883749191141996 0.0124357145512975"
      rpy="-1.57079646161027 -0.699913541621339 -0.694444981452453" />
    <parent
      link="Link_A5" />
    <child
      link="Link_A6" />
    <axis
      xyz="0 0 0.999999999999972" />
    <limit
      lower="-6.2"
      upper="6.2"
      effort="100"
      velocity="50" />
  </joint>
  <link
    name="gripper1_joint_L1">
    <inertial>
      <origin
        xyz="0.0193485447750683 0.0118828476099397 0.00284999999999991"
        rpy="0 0 0" />
      <mass
        value="0.000941962264171641" />
      <inertia
        ixx="3.71698394795775E-09"
        ixy="6.46234853557053E-26"
        ixz="2.68833699079734E-24"
        iyy="3.71698394795775E-09"
        iyz="1.93870456067116E-24"
        izz="4.66459883925088E-09" />
    </inertial>
    <visual>
      <origin
        xyz="0 0 0"
        rpy="0 0 0" />
      <geometry>
        <mesh
          filename="../meshes/gripper1_joint_L1.STL" />
      </geometry>
      <material
        name="">
        <color
          rgba="0.647058823529412 0.619607843137255 0.588235294117647 1" />
      </material>
    </visual>
    <collision>
      <origin
        xyz="0 0 0"
        rpy="0 0 0" />
      <geometry>
        <mesh
          filename="../meshes/gripper1_joint_L1.STL" />
      </geometry>
    </collision>
  </link>
  <joint
    name="joint_L1"
    type="revolute">
    <origin
      xyz="0.0287436344008424 -0.00953338282129984 0.171668647520541"
      rpy="1.57079661563452 -0.608970776956548 -0.419093504395419" />
    <parent
      link="Link_A6" />
    <child
      link="gripper1_joint_L1" />
    <axis
      xyz="0 0 -1" />
    <limit
      lower="-1.5"
      upper="1.5"
      effort="100"
      velocity="5" />
  </joint>
  <link
    name="gripper1_joint_L11">
    <inertial>
      <origin
        xyz="-0.00547756233416546 -0.0220453575041241 0.00234999999999985"
        rpy="0 0 0" />
      <mass
        value="0.000941962264171641" />
      <inertia
        ixx="3.71698394795776E-09"
        ixy="1.68021061924834E-25"
        ixz="2.06795153138257E-25"
        iyy="3.71698394795776E-09"
        iyz="-1.55096364853693E-25"
        izz="4.66459883925089E-09" />
    </inertial>
    <visual>
      <origin
        xyz="0 0 0"
        rpy="0 0 0" />
      <geometry>
        <mesh
          filename="../meshes/gripper1_joint_L11.STL" />
      </geometry>
      <material
        name="">
        <color
          rgba="0.647058823529412 0.619607843137255 0.588235294117647 1" />
      </material>
    </visual>
    <collision>
      <origin
        xyz="0 0 0"
        rpy="0 0 0" />
      <geometry>
        <mesh
          filename="../meshes/gripper1_joint_L11.STL" />
      </geometry>
    </collision>
  </link>
  <joint
    name="joint_L11"
    type="revolute">
    <origin
      xyz="-0.0263219176910475 0.0149975228847674 0.171647022948943"
      rpy="-1.57079662537937 0.654311324220914 2.72249913269507" />
    <parent
      link="Link_A6" />
    <child
      link="gripper1_joint_L11" />
    <axis
      xyz="0 0 -1" />
    <limit
      lower="-3.14"
      upper="3.14"
      effort="100"
      velocity="5" />
  </joint>
  <link
    name="Link_B1">
    <inertial>
      <origin
        xyz="-0.0210307613582223 -0.0018029682366224 0.0768121445945208"
        rpy="0 0 0" />
      <mass
        value="0.593520735842376" />
      <inertia
        ixx="0.00118220902268505"
        ixy="-7.13360807959133E-06"
        ixz="0.000210418401826395"
        iyy="0.00126545372417533"
        iyz="1.79133915985154E-05"
        izz="0.000561301309181966" />
    </inertial>
    <visual>
      <origin
        xyz="0 0 0"
        rpy="0 0 0" />
      <geometry>
        <mesh
          filename="../meshes/Link_B1.STL" />
      </geometry>
      <material
        name="">
        <color
          rgba="1 1 1 1" />
      </material>
    </visual>
    <collision>
      <origin
        xyz="0 0 0"
        rpy="0 0 0" />
      <geometry>
        <mesh
          filename="../meshes/Link_B1.STL" />
      </geometry>
    </collision>
  </link>
  <joint
    name="joint_platform_B1"
    type="revolute">
    <origin
      xyz="-0.142473632839857 0.155636147433961 -0.227311716711636"
      rpy="-1.57079632679501 0 0.744063112694143" />
    <parent
      link="platform_link" />
    <child
      link="Link_B1" />
    <axis
      xyz="0 0 1" />
    <limit
      lower="-3.1"
      upper="3.1"
      effort="100"
      velocity="50" />
  </joint>
  <link
    name="Link_B2">
    <inertial>
      <origin
        xyz="-0.05129234753464 0.143368762266122 -0.022663815567925"
        rpy="0 0 0" />
      <mass
        value="0.86418023642289" />
      <inertia
        ixx="0.00189155350029881"
        ixy="0.000450453971938174"
        ixz="-0.000142032222820076"
        iyy="0.000793701619531189"
        iyz="0.000396980897230203"
        izz="0.00195281240968516" />
    </inertial>
    <visual>
      <origin
        xyz="0 0 0"
        rpy="0 0 0" />
      <geometry>
        <mesh
          filename="../meshes/Link_B2.STL" />
      </geometry>
      <material
        name="">
        <color
          rgba="1 1 1 1" />
      </material>
    </visual>
    <collision>
      <origin
        xyz="0 0 0"
        rpy="0 0 0" />
      <geometry>
        <mesh
          filename="../meshes/Link_B2.STL" />
      </geometry>
    </collision>
  </link>
  <joint
    name="joint_platform_B2"
    type="revolute">
    <origin
      xyz="0.0164025952708852 0.00137401341327159 0.102000000000029"
      rpy="0.0849621690785075 1.5707963267949 0" />
    <parent
      link="Link_B1" />
    <child
      link="Link_B2" />
    <axis
      xyz="0 0 1" />
    <limit
      lower="-2.26"
      upper="2.26"
      effort="100"
      velocity="50" />
  </joint>
  <link
    name="Link_B3">
    <inertial>
      <origin
        xyz="-0.0445835519365935 0.0396010729673631 0.00266699546761176"
        rpy="0 0 0" />
      <mass
        value="0.289639334892493" />
      <inertia
        ixx="0.000368538526302153"
        ixy="0.000238752152606206"
        ixz="0.000108127863740364"
        iyy="0.00042530023019444"
        iyz="-9.60150249020287E-05"
        izz="0.000614165798652773" />
    </inertial>
    <visual>
      <origin
        xyz="0 0 0"
        rpy="0 0 0" />
      <geometry>
        <mesh
          filename="../meshes/Link_B3.STL" />
      </geometry>
      <material
        name="">
        <color
          rgba="1 1 1 1" />
      </material>
    </visual>
    <collision>
      <origin
        xyz="0 0 0"
        rpy="0 0 0" />
      <geometry>
        <mesh
          filename="../meshes/Link_B3.STL" />
      </geometry>
    </collision>
  </link>
  <joint
    name="joint_platform_B3"
    type="revolute">
    <origin
      xyz="-0.0862037470031803 0.241063204199487 -0.00352514725905964"
      rpy="3.14159265358979 0 -0.0919224225404343" />
    <parent
      link="Link_B2" />
    <child
      link="Link_B3" />
    <axis
      xyz="0 0 1" />
    <limit
      lower="-2.26"
      upper="2.26"
      effort="100"
      velocity="50" />
  </joint>
  <link
    name="Link_B4">
    <inertial>
      <origin
        xyz="-0.00734522629108841 0.0164811078491406 -0.0599618100808766"
        rpy="0 0 0" />
      <mass
        value="0.239430613356859" />
      <inertia
        ixx="0.000282116069340485"
        ixy="8.619121975907E-06"
        ixz="-1.79748327822413E-05"
        iyy="0.000266568837663141"
        iyz="4.04244202966507E-05"
        izz="0.000119899571670422" />
    </inertial>
    <visual>
      <origin
        xyz="0 0 0"
        rpy="0 0 0" />
      <geometry>
        <mesh
          filename="../meshes/Link_B4.STL" />
      </geometry>
      <material
        name="">
        <color
          rgba="1 1 1 1" />
      </material>
    </visual>
    <collision>
      <origin
        xyz="0 0 0"
        rpy="0 0 0" />
      <geometry>
        <mesh
          filename="../meshes/Link_B4.STL" />
      </geometry>
    </collision>
  </link>
  <joint
    name="joint_platform_B4"
    type="revolute">
    <origin
      xyz="-0.0960920462857941 0.0853717682345888 0.013226827485807"
      rpy="1.57079632679491 1.01854263840748 0.844439767031704" />
    <parent
      link="Link_B3" />
    <child
      link="Link_B4" />
    <axis
      xyz="0 0 1" />
    <limit
      lower="-3.14"
      upper="3.14"
      effort="100"
      velocity="50" />
  </joint>
  <link
    name="Link_B5">
    <inertial>
      <origin
        xyz="0.0113936099776971 0.0581872091852206 0.00506814577202197"
        rpy="0 0 0" />
      <mass
        value="0.218793312303163" />
      <inertia
        ixx="0.000341452636306923"
        ixy="-4.6320357829731E-05"
        ixz="-1.50283451284409E-05"
        iyy="0.000113994702339846"
        iyz="-7.67811878497607E-05"
        izz="0.000334463188331327" />
    </inertial>
    <visual>
      <origin
        xyz="0 0 0"
        rpy="0 0 0" />
      <geometry>
        <mesh
          filename="../meshes/Link_B5.STL" />
      </geometry>
      <material
        name="">
        <color
          rgba="1 1 1 1" />
      </material>
    </visual>
    <collision>
      <origin
        xyz="0 0 0"
        rpy="0 0 0" />
      <geometry>
        <mesh
          filename="../meshes/Link_B5.STL" />
      </geometry>
    </collision>
  </link>
  <joint
    name="joint_platform_B5"
    type="revolute">
    <origin
      xyz="0.00498093355069423 -0.0110668807595307 -0.0815561902327434"
      rpy="-1.5707963267949 -0.573741362025699 0.418364132516817" />
    <parent
      link="Link_B4" />
    <child
      link="Link_B5" />
    <axis
      xyz="0 0 1" />
    <limit
      lower="-2.2"
      upper="2.2"
      effort="100"
      velocity="50" />
  </joint>
  <link
    name="Link_B6">
    <inertial>
      <origin
        xyz="-0.00294730022944073 0.0251822049216943 0.0565997798247693"
        rpy="0 0 0" />
      <mass
        value="0.451431434138226" />
      <inertia
        ixx="0.000247729151832058"
        ixy="1.41219601118001E-05"
        ixz="1.34224418449947E-08"
        iyy="0.00012948082155834"
        iyz="-3.08228001316928E-08"
        izz="0.000355045211995034" />
    </inertial>
    <visual>
      <origin
        xyz="0 0 0"
        rpy="0 0 0" />
      <geometry>
        <mesh
          filename="../meshes/Link_B6.STL" />
      </geometry>
      <material
        name="">
        <color
          rgba="1 1 1 1" />
      </material>
    </visual>
    <collision>
      <origin
        xyz="0 0 0"
        rpy="0 0 0" />
      <geometry>
        <mesh
          filename="../meshes/Link_B6.STL" />
      </geometry>
    </collision>
  </link>
  <joint
    name="joint_platform_B6"
    type="revolute">
    <origin
      xyz="0.0220769553081411 0.112769294031951 0.0124298510263973"
      rpy="-1.5707963267949 0.363602003221376 -0.193504212101692" />
    <parent
      link="Link_B5" />
    <child
      link="Link_B6" />
    <axis
      xyz="0 0 1" />
    <limit
      lower="-6.2"
      upper="6.2"
      effort="100"
      velocity="50" />
  </joint>
  <link
    name="gripper1_joint_R1">
    <inertial>
      <origin
        xyz="0.0118015077503003 0.0201258898652393 0.00285000000000057"
        rpy="0 0 0" />
      <mass
        value="0.000941962264171641" />
      <inertia
        ixx="3.71698394795775E-09"
        ixy="-1.55096364853693E-25"
        ixz="-6.20385459414771E-25"
        iyy="3.71698394795775E-09"
        iyz="1.75775880167518E-24"
        izz="4.66459883925088E-09" />
    </inertial>
    <visual>
      <origin
        xyz="0 0 0"
        rpy="0 0 0" />
      <geometry>
        <mesh
          filename="../meshes/gripper1_joint_R1.STL" />
      </geometry>
      <material
        name="">
        <color
          rgba="0.647058823529412 0.619607843137255 0.588235294117647 1" />
      </material>
    </visual>
    <collision>
      <origin
        xyz="0 0 0"
        rpy="0 0 0" />
      <geometry>
        <mesh
          filename="../meshes/gripper1_joint_R1.STL" />
      </geometry>
    </collision>
  </link>
  <joint
    name="joint_R1"
    type="revolute">
    <origin
      xyz="0.0295907775490525 0.00649223429478463 0.171668646802052"
      rpy="1.5707963267949 -0.182359123558308 0.117102273402236" />
    <parent
      link="Link_B6" />
    <child
      link="gripper1_joint_R1" />
    <axis
      xyz="0 0 -1" />
    <limit
      lower="-1.5"
      upper="1.5"
      effort="100"
      velocity="5" />
  </joint>
  <link
    name="gripper1_joint_R11">
    <inertial>
      <origin
        xyz="-0.00514362268148821 0.0221256552968719 0.00235000000000096"
        rpy="0 0 0" />
      <mass
        value="0.000941962264171637" />
      <inertia
        ixx="3.71698394795773E-09"
        ixy="-5.16987882845642E-26"
        ixz="-6.20385459414771E-25"
        iyy="3.71698394795773E-09"
        iyz="-1.75775880167518E-24"
        izz="4.66459883925086E-09" />
    </inertial>
    <visual>
      <origin
        xyz="0 0 0"
        rpy="0 0 0" />
      <geometry>
        <mesh
          filename="../meshes/gripper1_joint_R11.STL" />
      </geometry>
      <material
        name="">
        <color
          rgba="0.647058823529412 0.619607843137255 0.588235294117647 1" />
      </material>
    </visual>
    <collision>
      <origin
        xyz="0 0 0"
        rpy="0 0 0" />
      <geometry>
        <mesh
          filename="../meshes/gripper1_joint_R11.STL" />
      </geometry>
    </collision>
  </link>
  <joint
    name="joint_R11"
    type="revolute">
    <origin
      xyz="-0.0302788739118513 -0.000550861324005947 0.171647022251381"
      rpy="1.5707963267949 -0.182359123558308 0.117102273402236" />
    <parent
      link="Link_B6" />
    <child
      link="gripper1_joint_R11" />
    <axis
      xyz="0 0 -1" />
    <limit
      lower="-1.5"
      upper="1.5"
      effort="100"
      velocity="5" />
  </joint>
  <link
    name="Link_S1">
    <inertial>
      <origin
        xyz="-0.00111431623367673 -0.000394920204415852 -0.027976557476941"
        rpy="0 0 0" />
      <mass
        value="0.106878620604356" />
      <inertia
        ixx="7.78786903515349E-05"
        ixy="-1.60681975184578E-08"
        ixz="2.61075287396989E-06"
        iyy="9.22279471336507E-05"
        iyz="2.93084723436218E-07"
        izz="8.34708373040095E-05" />
    </inertial>
    <visual>
      <origin
        xyz="0 0 0"
        rpy="0 0 0" />
      <geometry>
        <mesh
          filename="../meshes/Link_S1.STL" />
      </geometry>
      <material
        name="">
        <color
          rgba="1 1 1 1" />
      </material>
    </visual>
    <collision>
      <origin
        xyz="0 0 0"
        rpy="0 0 0" />
      <geometry>
        <mesh
          filename="../meshes/Link_S1.STL" />
      </geometry>
    </collision>
  </link>
  <joint
    name="joint_platform_S1"
    type="revolute">
    <origin
      xyz="0.000433041860730524 0.000398644471470921 -0.39995"
      rpy="0 0 0" />
    <parent
      link="platform_link" />
    <child
      link="Link_S1" />
    <axis
      xyz="0 0 1" />
    <limit
      lower="-2.68"
      upper="2.68"
      effort="100"
      velocity="50" />
  </joint>
  <link
    name="Link_S2">
    <inertial>
      <origin
        xyz="0.0724194778767879 -0.131936188075807 0.044406043154082"
        rpy="0 0 0" />
      <mass
        value="0.203920919386394" />
      <inertia
        ixx="0.00128889812936827"
        ixy="0.00066263638005062"
        ixz="-7.91150391912718E-06"
        iyy="0.000642111780427921"
        iyz="3.83146896594997E-07"
        izz="0.00162755121218312" />
    </inertial>
    <visual>
      <origin
        xyz="0 0 0"
        rpy="0 0 0" />
      <geometry>
        <mesh
          filename="../meshes/Link_S2.STL" />
      </geometry>
      <material
        name="">
        <color
          rgba="1 1 1 1" />
      </material>
    </visual>
    <collision>
      <origin
        xyz="0 0 0"
        rpy="0 0 0" />
      <geometry>
        <mesh
          filename="../meshes/Link_S2.STL" />
      </geometry>
    </collision>
  </link>
  <joint
    name="joint_platform_S2"
    type="revolute">
    <origin
      xyz="0.0367444027969984 0.00064137593620528 -0.0370499999999101"
      rpy="1.5707963267949 0 -1.5533430342851" />
    <parent
      link="Link_S1" />
    <child
      link="Link_S2" />
    <axis
      xyz="0 0 1" />
    <limit
      lower="0"
      upper="3.3"
      effort="100"
      velocity="50" />
  </joint>
  <link
    name="Link_S3">
    <inertial>
      <origin
        xyz="0.100943213162187 -0.0283683578342203 0.0476334565574921"
        rpy="0 0 0" />
      <mass
        value="0.259290582671513" />
      <inertia
        ixx="9.87188428452086E-05"
        ixy="1.87582848560715E-05"
        ixz="-9.74231758607964E-07"
        iyy="0.00018114878198025"
        iyz="6.25962927670279E-07"
        izz="0.000209231319367455" />
    </inertial>
    <visual>
      <origin
        xyz="0 0 0"
        rpy="0 0 0" />
      <geometry>
        <mesh
          filename="../meshes/Link_S3.STL" />
      </geometry>
      <material
        name="">
        <color
          rgba="1 1 1 1" />
      </material>
    </visual>
    <collision>
      <origin
        xyz="0 0 0"
        rpy="0 0 0" />
      <geometry>
        <mesh
          filename="../meshes/Link_S3.STL" />
      </geometry>
    </collision>
  </link>
  <joint
    name="joint_platform_S3"
    type="revolute">
    <origin
      xyz="0.162822697705282 -0.233968487158141 -0.0104499999999984"
      rpy="0 0 0" />
    <parent
      link="Link_S2" />
    <child
      link="Link_S3" />
    <axis
      xyz="0 0 1" />
    <limit
      lower="0"
      upper="3.14"
      effort="100"
      velocity="50" />
  </joint>
  <link
    name="Link_S4">
    <inertial>
      <origin
        xyz="0.0010759185525 -0.000204149505515172 0.0322093232269932"
        rpy="0 0 0" />
      <mass
        value="0.120706963047308" />
      <inertia
        ixx="4.59016732660943E-05"
        ixy="2.29836809855153E-08"
        ixz="6.83876846477265E-08"
        iyy="3.6618670401351E-05"
        iyz="-4.66820691740301E-08"
        izz="3.90050008284305E-05" />
    </inertial>
    <visual>
      <origin
        xyz="0 0 0"
        rpy="0 0 0" />
      <geometry>
        <mesh
          filename="../meshes/Link_S4.STL" />
      </geometry>
      <material
        name="">
        <color
          rgba="1 1 1 1" />
      </material>
    </visual>
    <collision>
      <origin
        xyz="0 0 0"
        rpy="0 0 0" />
      <geometry>
        <mesh
          filename="../meshes/Link_S4.STL" />
      </geometry>
    </collision>
  </link>
  <joint
    name="joint_platform_S4"
    type="revolute">
    <origin
      xyz="0.210129289624401 -0.0494636890451812 0.047199999999998"
      rpy="1.57079632679571 1.56854804510877 1.44163329792559" />
    <parent
      link="Link_S3" />
    <child
      link="Link_S4" />
    <axis
      xyz="0 0 -1" />
    <limit
      lower="-1.55"
      upper="1.55"
      effort="100"
      velocity="50" />
  </joint>
  <link
    name="Link_S5">
    <inertial>
      <origin
        xyz="3.87216944853774E-05 -0.0573117732740405 -0.0211795210933351"
        rpy="0 0 0" />
      <mass
        value="0.136460062693172" />
      <inertia
        ixx="0.000120531193110392"
        ixy="-2.72999648307107E-07"
        ixz="4.65206341731827E-08"
        iyy="6.56087190659654E-05"
        iyz="-2.43327384342589E-05"
        izz="0.000114403333421258" />
    </inertial>
    <visual>
      <origin
        xyz="0 0 0"
        rpy="0 0 0" />
      <geometry>
        <mesh
          filename="../meshes/Link_S5.STL" />
      </geometry>
      <material
        name="">
        <color
          rgba="1 1 1 1" />
      </material>
    </visual>
    <collision>
      <origin
        xyz="0 0 0"
        rpy="0 0 0" />
      <geometry>
        <mesh
          filename="../meshes/Link_S5.STL" />
      </geometry>
    </collision>
  </link>
  <joint
    name="joint_platform_S5"
    type="revolute">
    <origin
      xyz="0.0239199395449672 -5.37788526262517E-05 0.0369999999999999"
      rpy="1.57079632679489 -1.4416332979245 1.56854804510879" />
    <parent
      link="Link_S4" />
    <child
      link="Link_S5" />
    <axis
      xyz="0 0 -1" />
    <limit
      lower="-1.55"
      upper="1.55"
      effort="100"
      velocity="50" />
  </joint>
  <link
    name="Link_S6">
    <inertial>
      <origin
        xyz="0.000874537749214421 -0.0417696007733942 0.0121227761487945"
        rpy="0 0 0" />
      <mass
        value="0.319123225490564" />
      <inertia
        ixx="0.000210288101608249"
        ixy="5.15533868165301E-09"
        ixz="6.73512565951391E-07"
        iyy="0.000226598972704927"
        iyz="-2.80611239630406E-07"
        izz="0.000419233741366659" />
    </inertial>
    <visual>
      <origin
        xyz="0 0 0"
        rpy="0 0 0" />
      <geometry>
        <mesh
          filename="../meshes/Link_S6.STL" />
      </geometry>
      <material
        name="">
        <color
          rgba="0.898039215686275 0.917647058823529 0.929411764705882 1" />
      </material>
    </visual>
    <collision>
      <origin
        xyz="0 0 0"
        rpy="0 0 0" />
      <geometry>
        <mesh
          filename="../meshes/Link_S6.STL" />
      </geometry>
    </collision>
  </link>
  <joint
    name="joint_platform_S6"
    type="revolute">
    <origin
      xyz="0 -0.0909999999999964 -0.0249165214861997"
      rpy="1.57079632679511 -1.55334303428509 0" />
    <parent
      link="Link_S5" />
    <child
      link="Link_S6" />
    <axis
      xyz="0 0 -1" />
    <limit
      lower="-3"
      upper="3"
      effort="100"
      velocity="50" />
  </joint>
  <link
    name="box_link">
    <inertial>
      <origin
        xyz="-0.000281606739832099 -3.97189127698816E-08 -0.081439091931118"
        rpy="0 0 0" />
      <mass
        value="5.57765292852931" />
      <inertia
        ixx="0.160527563681421"
        ixy="-1.08066372431341E-13"
        ixz="1.94871539327183E-15"
        iyy="0.222931123608603"
        iyz="2.80244562548696E-09"
        izz="0.303216770492903" />
    </inertial>
    <visual>
      <origin
        xyz="0 0 0"
        rpy="0 0 0" />
      <geometry>
        <mesh
          filename="../meshes/box_link.STL" />
      </geometry>
      <material
        name="">
        <color
          rgba="0.96078431372549 1 0.341176470588235 1" />
      </material>
    </visual>
   <collision>
    <origin xyz="0 0 0.005" rpy="0 0 0"/>
    <geometry>
      <box size="0.5 0.4 0.01"/>
    </geometry>
  </collision>

  <collision>
    <origin xyz="0 0.195 0.125" rpy="0 0 0"/>
    <geometry>
      <box size="0.5 0.01 0.25"/>
    </geometry>
  </collision>

  <collision>
    <origin xyz="0 -0.195 0.125" rpy="0 0 0"/>
    <geometry>
      <box size="0.5 0.01 0.25"/>
    </geometry>
  </collision>

  <collision>
    <origin xyz="-0.245 0 0.125" rpy="0 0 0"/>
    <geometry>
      <box size="0.01 0.4 0.25"/>
    </geometry>
  </collision>

  <collision>
    <origin xyz="0.245 0 0.125" rpy="0 0 0"/>
    <geometry>
      <box size="0.01 0.4 0.25"/>
    </geometry>
  </collision>
  </link>
  <joint
    name="J_box1"
    type="fixed">
    <origin
      xyz="-0.02812 -0.43858 0.3575"
      rpy="0 0 0" />
    <parent
      link="base_link" />
    <child
      link="box_link" />
    <axis
      xyz="0 0 0" />
  </joint>
  <link
    name="Sbox1">
    <inertial>
      <origin
        xyz="-0.0294521228117989 -0.0181434301400363 -0.00321227754553127"
        rpy="0 0 0" />
      <mass
        value="0.891461835933509" />
      <inertia
        ixx="0.0069458426853299"
        ixy="0.00143955862764452"
        ixz="-6.54109835378711E-06"
        iyy="0.00493625296740043"
        iyz="-5.64676492921899E-06"
        izz="0.00611318081333504" />
    </inertial>
    <visual>
      <origin
        xyz="0 0 0"
        rpy="0 0 0" />
      <geometry>
        <mesh
          filename="../meshes/Sbox1.STL" />
      </geometry>
      <material
        name="">
        <color
          rgba="1 0.737254901960784 0.247058823529412 1" />
      </material>
    </visual>
    <collision>
      <origin
        xyz="0 0 0"
        rpy="0 0 0" />
      <geometry>
        <mesh
          filename="../meshes/Sbox1.STL" />
      </geometry>
    </collision>
  </link>
  <joint
    name="j_Sbox1"
    type="fixed">
    <origin
      xyz="0.45561 0.40413 0.1235"
      rpy="-1.5708 0 -1.5708" />
    <parent
      link="base_link" />
    <child
      link="Sbox1" />
    <axis
      xyz="0 0 0" />
  </joint>
  <link
    name="Sbox2">
    <inertial>
      <origin
        xyz="-0.0294521228117987 -0.0181434301400364 -0.0032122775455311"
        rpy="0 0 0" />
      <mass
        value="0.891461835933508" />
      <inertia
        ixx="0.00694584268532987"
        ixy="0.00143955862764451"
        ixz="-6.54109835378696E-06"
        iyy="0.00493625296740038"
        iyz="-5.64676492923127E-06"
        izz="0.00611318081333495" />
    </inertial>
    <visual>
      <origin
        xyz="0 0 0"
        rpy="0 0 0" />
      <geometry>
        <mesh
          filename="../meshes/Sbox2.STL" />
      </geometry>
      <material
        name="">
        <color
          rgba="1 0.737254901960784 0.247058823529412 1" />
      </material>
    </visual>
    <collision>
      <origin
        xyz="0 0 0"
        rpy="0 0 0" />
      <geometry>
        <mesh
          filename="../meshes/Sbox2.STL" />
      </geometry>
    </collision>
  </link>
  <joint
    name="J_Sbox2"
    type="fixed">
    <origin
      xyz="0.0041491 0.40508 0.1005"
      rpy="-1.5708 0 -1.5708" />
    <parent
      link="base_link" />
    <child
      link="Sbox2" />
    <axis
      xyz="0 0 0" />
  </joint>
  <link
    name="base2">
    <inertial>
      <origin
        xyz="-1.11022302462516E-16 -0.005 -2.08166817117217E-17"
        rpy="0 0 0" />
      <mass
        value="7.29000000000001" />
      <inertia
        ixx="0.21876075"
        ixy="-2.00406097966565E-19"
        ixz="-4.33949751132979E-17"
        iyy="0.34171875"
        iyz="-1.76232317127185E-35"
        izz="0.1230795" />
    </inertial>
    <visual>
      <origin
        xyz="0 0 0"
        rpy="0 0 0" />
      <geometry>
        <mesh
          filename="../meshes/base2.STL" />
      </geometry>
      <material
        name="">
        <color
          rgba="0.898039215686275 0.917647058823529 0.929411764705882 1" />
      </material>
    </visual>
    <collision>
      <origin
        xyz="0 0 0"
        rpy="0 0 0" />
      <geometry>
        <mesh
          filename="../meshes/base2.STL" />
      </geometry>
    </collision>
  </link>
  <joint
    name="J_base2"
    type="fixed">
    <origin
      xyz="0.55043 -0.10818 0.1895"
      rpy="-1.5708 0 0" />
    <parent
      link="base_link" />
    <child
      link="base2" />
    <axis
      xyz="0 0 0" />
  </joint>
  <link
    name="base3">
    <inertial>
      <origin
        xyz="-1.38777878078145E-17 0 -0.005"
        rpy="0 0 0" />
      <mass
        value="5.56875" />
      <inertia
        ixx="0.0653051953125"
        ixy="-9.57242098087451E-18"
        ixz="-6.41332690079492E-20"
        iyy="0.1404253125"
        iyz="-2.66214405999079E-35"
        izz="0.2056376953125" />
    </inertial>
    <visual>
      <origin
        xyz="0 0 0"
        rpy="0 0 0" />
      <geometry>
        <mesh
          filename="../meshes/base3.STL" />
      </geometry>
      <material
        name="">
        <color
          rgba="0.898039215686275 0.917647058823529 0.929411764705882 1" />
      </material>
    </visual>
    <collision>
      <origin
        xyz="0 0 0"
        rpy="0 0 0" />
      <geometry>
        <mesh
          filename="../meshes/base3.STL" />
      </geometry>
    </collision>
  </link>
  <joint
    name="J_base3"
    type="fixed">
    <origin
      xyz="0.00043304 0.32032 0.1895"
      rpy="3.1416 0 0" />
    <parent
      link="base_link" />
    <child
      link="base3" />
    <axis
      xyz="0 0 0" />
  </joint>
  <link
    name="bsae4">
    <inertial>
      <origin
        xyz="-0.0207923626368445 0.343067630222129 -0.468696236768628"
        rpy="0 0 0" />
      <mass
        value="30.8708694684072" />
      <inertia
        ixx="1.30034713911167"
        ixy="-0.00689651218188683"
        ixz="-0.00333912195466688"
        iyy="1.02368809303574"
        iyz="-0.00199183641909817"
        izz="2.20172657520933" />
    </inertial>
    <visual>
      <origin
        xyz="0 0 0"
        rpy="0 0 0" />
      <geometry>
        <mesh
          filename="../meshes/bsae4.STL" />
      </geometry>
      <material
        name="">
        <color
          rgba="1 1 1 1" />
      </material>
    </visual>
    <collision>
      <origin
        xyz="0 0 0"
        rpy="0 0 0" />
      <geometry>
        <mesh
          filename="../meshes/bsae4.STL" />
      </geometry>
    </collision>
  </link>
  <joint
    name="J_base4"
    type="fixed">
    <origin
      xyz="0.00043304 -0.030452 0.0395"
      rpy="-3.1416 0 0" />
    <parent
      link="base_link" />
    <child
      link="bsae4" />
    <axis
      xyz="0 0 0" />
  </joint>
  <link
    name="PD">
    <inertial>
      <origin
        xyz="0.00866292295340547 0.288225896921182 -0.0425527820625178"
        rpy="0 0 0" />
      <mass
        value="41.4799763839389" />
      <inertia
        ixx="0.609619080743764"
        ixy="0.00198697458753424"
        ixz="4.19438264141395E-05"
        iyy="8.59452645574208"
        iyz="2.77933127686186E-05"
        izz="9.00871905491377" />
    </inertial>
    <visual>
      <origin
        xyz="0 0 0"
        rpy="0 0 0" />
      <geometry>
        <mesh
          filename="../meshes/PD.STL" />
      </geometry>
      <material
        name="">
        <color
          rgba="0.792156862745098 0.819607843137255 0.933333333333333 1" />
      </material>
    </visual>
    <collision>
      <origin
        xyz="0 0 0"
        rpy="0 0 0" />
      <geometry>
        <mesh
          filename="../meshes/PD.STL" />
      </geometry>
    </collision>
  </link>
  <joint
    name="J_PD"
    type="fixed">
    <origin
      xyz="0.02219 0.4272 0.2125"
      rpy="3.1416 0 0" />
    <parent
      link="base_link" />
    <child
      link="PD" />
    <axis
      xyz="0 0 0" />
  </joint>
</robot>