<?xml version="1.0" encoding="utf-8"?>
<!-- This URDF was automatically created by SolidWorks to URDF Exporter! Originally created by Stephen Brawner (brawner@gmail.com)
     Commit Version: 1.6.0-4-g7f85cfe  Build Version: 1.6.7995.38578
     For more information, please see http://wiki.ros.org/sw_urdf_exporter -->
<robot
  name="robot_V13">
  <!-- World root link for proper articulation structure in Isaac Sim -->
  <link name="World"/>

  <!-- Fixed joint connecting World to base_link -->
  <joint name="world_to_base" type="fixed">
    <parent link="World"/>
    <child link="base_link"/>
    <origin xyz="0 0 0" rpy="0 0 0"/>
  </joint>

  <link
    name="base_link">
    <inertial>
      <origin
        xyz="0.0350225134736962 -0.045653549564831 0.267035863945469"
        rpy="0 0 0" />
      <mass
        value="289.278432762858" />
      <inertia
        ixx="9.23659204469314"
        ixy="0.00488951210528622"
        ixz="0.00330658007223796"
        iyy="19.3651626709836"
        iyz="0.513621947132372"
        izz="22.3286664811058" />
    </inertial>
    <visual>
      <origin
        xyz="0 0 0"
        rpy="0 0 0" />
      <geometry>
        <mesh
          filename="../meshes/base_link.STL" />
      </geometry>
      <material
        name="">
        <color
          rgba="0.792156862745098 0.819607843137255 0.933333333333333 1" />
      </material>
    </visual>
    <collision>
      <origin
        xyz="0 0 0"
        rpy="0 0 0" />
      <geometry>
        <mesh
          filename="../meshes/base_link.STL" />
      </geometry>
    </collision>
  </link>
  <link
    name="platform_link">
    <inertial>
      <origin
        xyz="0.00669542627058103 0.0327387114637423 -0.197541586318534"
        rpy="0 0 0" />
      <mass
        value="5.62676904597552" />
      <inertia
        ixx="0.032912619778256"
        ixy="-0.00101982319674113"
        ixz="-7.8232029828291E-06"
        iyy="0.0330812050692955"
        iyz="-5.06524274225643E-05"
        izz="0.0111162517830387" />
    </inertial>
    <visual>
      <origin
        xyz="0 0 0"
        rpy="0 0 0" />
      <geometry>
        <mesh
          filename="../meshes/platform_link.STL" />
      </geometry>
      <material
        name="">
        <color
          rgba="0.898039215686275 0.917647058823529 0.929411764705882 1" />
      </material>
    </visual>
    <collision>
      <origin
        xyz="0 0 0"
        rpy="0 0 0" />
      <geometry>
        <mesh
          filename="../meshes/platform_link.STL" />
      </geometry>
    </collision>
  </link>
  <joint
    name="joint_platform_D1"
    type="revolute">
    <origin
      xyz="0 0 0"
      rpy="0 0 0" />
    <parent
      link="base_link" />
    <child
      link="platform_link" />
    <axis
      xyz="0 0 -1" />
    <limit
      lower="-3.14"
      upper="3.14"
      effort="100"
      velocity="50" />
  </joint>
  <link
    name="Link_A1">
    <inertial>
      <origin
        xyz="0.0169308367894223 0.0125928013215484 0.0768128774242119"
        rpy="0 0 0" />
      <mass
        value="0.593525762282562" />
      <inertia
        ixx="0.001211740353914"
        ixy="-4.04510751675718E-05"
        ixz="-0.000169403894082202"
        iyy="0.00123597531032555"
        iyz="-0.000126111277061559"
        izz="0.000561310092473764" />
    </inertial>
    <visual>
      <origin
        xyz="0 0 0"
        rpy="0 0 0" />
      <geometry>
        <mesh
          filename="../meshes/Link_A1.STL" />
      </geometry>
      <material
        name="">
        <color
          rgba="1 1 1 1" />
      </material>
    </visual>
    <collision>
      <origin
        xyz="0 0 0"
        rpy="0 0 0" />
      <geometry>
        <mesh
          filename="../meshes/Link_A1.STL" />
      </geometry>
    </collision>
  </link>
  <joint
    name="joint_platform_A1"
    type="revolute">
    <origin
      xyz="0.156472683129336 0.142433967655858 -0.227311716711955"
      rpy="-1.57079632679501 0 -0.826733214100753" />
    <parent
      link="platform_link" />
    <child
      link="Link_A1" />
    <axis
      xyz="0 0 1" />
    <limit
      lower="-3.14"
      upper="3.14"
      effort="100"
      velocity="50" />
  </joint>
  <link
    name="Link_A2">
    <inertial>
      <origin
        xyz="-0.0126344741021581 -0.151722416609147 0.0226638907893547"
        rpy="0 0 0" />
      <mass
        value="0.864181214181756" />
      <inertia
        ixx="0.00204291594675937"
        ixy="-0.000117497060965045"
        ixz="3.49972816263209E-05"
        iyy="0.000642323165198608"
        iyz="0.00042016637411416"
        izz="0.00195279777242341" />
    </inertial>
    <visual>
      <origin
        xyz="0 0 0"
        rpy="0 0 0" />
      <geometry>
        <mesh
          filename="../meshes/Link_A2.STL" />
      </geometry>
      <material
        name="">
        <color
          rgba="1 1 1 1" />
      </material>
    </visual>
    <collision>
      <origin
        xyz="0 0 0"
        rpy="0 0 0" />
      <geometry>
        <mesh
          filename="../meshes/Link_A2.STL" />
      </geometry>
    </collision>
  </link>
  <joint
    name="joint_platform_A2"
    type="revolute">
    <origin
      xyz="-0.013211 -0.009832 0.102"
      rpy="-1.5708 -1.0682 -0.93088" />
    <parent
      link="Link_A1" />
    <child
      link="Link_A2" />
    <axis
      xyz="0 0 1" />
    <limit
      lower="-2.26"
      upper="2.26"
      effort="100"
      velocity="50" />
  </joint>
  <link
    name="Link_A3">
    <inertial>
      <origin
        xyz="0.0578270527827575 -0.0144992229203418 0.00266652314198285"
        rpy="0 0 0" />
      <mass
        value="0.289645597916636" />
      <inertia
        ixx="0.000184905939167842"
        ixy="0.000113389601168155"
        ixz="-0.000140277049300771"
        iyy="0.000608954956903588"
        iyz="3.51374260818499E-05"
        izz="0.000614182801459952" />
    </inertial>
    <visual>
      <origin
        xyz="0 0 0"
        rpy="0 0 0" />
      <geometry>
        <mesh
          filename="../meshes/Link_A3.STL" />
      </geometry>
      <material
        name="">
        <color
          rgba="1 1 1 1" />
      </material>
    </visual>
    <collision>
      <origin
        xyz="0 0 0"
        rpy="0 0 0" />
      <geometry>
        <mesh
          filename="../meshes/Link_A3.STL" />
      </geometry>
    </collision>
  </link>
  <joint
    name="joint_platform_A3"
    type="revolute">
    <origin
      xyz="-0.02127 -0.2551 0.0035251"
      rpy="0 0 0" />
    <parent
      link="Link_A2" />
    <child
      link="Link_A3" />
    <axis
      xyz="0 0 1" />
    <limit
      lower="-2.26"
      upper="2.26"
      effort="100"
      velocity="50" />
  </joint>
  <link
    name="Link_A4">
    <inertial>
      <origin
        xyz="0.016896007871893 -0.00633304037762816 -0.05996151419747"
        rpy="0 0 0" />
      <mass
        value="0.239433776027785" />
      <inertia
        ixx="0.000265607043125794"
        ixy="7.64305481199855E-06"
        ixz="4.14131935380001E-05"
        iyy="0.000283077940585531"
        iyz="-1.55624791539585E-05"
        izz="0.000119899346983553" />
    </inertial>
    <visual>
      <origin
        xyz="0 0 0"
        rpy="0 0 0" />
      <geometry>
        <mesh
          filename="../meshes/Link_A4.STL" />
      </geometry>
      <material
        name="">
        <color
          rgba="1 1 1 1" />
      </material>
    </visual>
    <collision>
      <origin
        xyz="0 0 0"
        rpy="0 0 0" />
      <geometry>
        <mesh
          filename="../meshes/Link_A4.STL" />
      </geometry>
    </collision>
  </link>
  <joint
    name="joint_platform_A4"
    type="revolute">
    <origin
      xyz="0.12466 -0.031269 0.013236"
      rpy="-1.5708 -1.2113 1.3251" />
    <parent
      link="Link_A3" />
    <child
      link="Link_A4" />
    <axis
      xyz="0 0 -1" />
    <limit
      lower="-3.14"
      upper="3.14"
      effort="100"
      velocity="50" />
  </joint>
  <link
    name="Link_A5">
    <inertial>
      <origin
        xyz="0.0380094230376776 0.0456440434886026 0.00506810747745645"
        rpy="0 0 0" />
      <mass
        value="0.218793807603732" />
      <inertia
        ixx="0.000249967614137682"
        ixy="-0.000120769356677445"
        ixz="-5.00570691133891E-05"
        iyy="0.000205481998419059"
        iyz="-6.01294670291514E-05"
        izz="0.000334465752993695" />
    </inertial>
    <visual>
      <origin
        xyz="0 0 0"
        rpy="0 0 0" />
      <geometry>
        <mesh
          filename="../meshes/Link_A5.STL" />
      </geometry>
      <material
        name="">
        <color
          rgba="1 1 1 1" />
      </material>
    </visual>
    <collision>
      <origin
        xyz="0 0 0"
        rpy="0 0 0" />
      <geometry>
        <mesh
          filename="../meshes/Link_A5.STL" />
      </geometry>
    </collision>
  </link>
  <joint
    name="joint_platform_A5"
    type="revolute">
    <origin
      xyz="-0.011361 0.0042683 -0.0815"
      rpy="1.5708 1.3251 1.2113" />
    <parent
      link="Link_A4" />
    <child
      link="Link_A5" />
    <axis
      xyz="0 0 1" />
    <limit
      lower="-2.2"
      upper="2.2"
      effort="100"
      velocity="50" />
  </joint>
  <link
    name="Link_A6">
    <inertial>
      <origin
        xyz="0.00606884565213639 0.0152502416830386 0.109538960794972"
        rpy="0 0 0" />
      <mass
        value="0.652237451823604" />
      <inertia
        ixx="0.000301203372093203"
        ixy="-4.46063215910981E-05"
        ixz="-4.21673354067884E-09"
        iyy="0.000220903467434786"
        iyz="-3.33580588515041E-08"
        izz="0.000367350798134239" />
    </inertial>
    <visual>
      <origin
        xyz="0 0 0"
        rpy="0 0 0" />
      <geometry>
        <mesh
          filename="../meshes/Link_A6.STL" />
      </geometry>
      <material
        name="">
        <color
          rgba="1 1 1 1" />
      </material>
    </visual>
    <collision>
      <origin
        xyz="0 0 0"
        rpy="0 0 0" />
      <geometry>
        <mesh
          filename="../meshes/Link_A6.STL" />
      </geometry>
    </collision>
  </link>
  <joint
    name="joint_platform_A6"
    type="revolute">
    <origin
      xyz="0.0736102642149934 0.0883749191141996 0.0124357145512975"
      rpy="-1.57079646161027 -0.699913541621339 -0.694444981452453" />
    <parent
      link="Link_A5" />
    <child
      link="Link_A6" />
    <axis
      xyz="0 0 0.999999999999972" />
    <limit
      lower="-6.2"
      upper="6.2"
      effort="100"
      velocity="50" />
  </joint>
  <link
    name="Link_B1">
    <inertial>
      <origin
        xyz="-0.0210307677045693 -0.00180296762531718 0.0768121489298764"
        rpy="0 0 0" />
      <mass
        value="0.593520652494392" />
      <inertia
        ixx="0.00118220895129829"
        ixy="-7.13362599303804E-06"
        ixz="0.000210418284594544"
        iyy="0.00126545347689259"
        iyz="1.7913404274321E-05"
        izz="0.000561301129753201" />
    </inertial>
    <visual>
      <origin
        xyz="0 0 0"
        rpy="0 0 0" />
      <geometry>
        <mesh
          filename="../meshes/Link_B1.STL" />
      </geometry>
      <material
        name="">
        <color
          rgba="1 1 1 1" />
      </material>
    </visual>
    <collision>
      <origin
        xyz="0 0 0"
        rpy="0 0 0" />
      <geometry>
        <mesh
          filename="../meshes/Link_B1.STL" />
      </geometry>
    </collision>
  </link>
  <joint
    name="joint_platform_B1"
    type="revolute">
    <origin
      xyz="-0.142473632839857 0.155636147433961 -0.227311716711636"
      rpy="-1.57079632679501 0 0.744063112694143" />
    <parent
      link="platform_link" />
    <child
      link="Link_B1" />
    <axis
      xyz="0 0 1" />
    <limit
      lower="-3.1"
      upper="3.1"
      effort="100"
      velocity="50" />
  </joint>
  <link
    name="Link_B2">
    <inertial>
      <origin
        xyz="-0.0512923555647222 0.143368774947795 -0.0226638192200043"
        rpy="0 0 0" />
      <mass
        value="0.864180135653825" />
      <inertia
        ixx="0.00189155343231143"
        ixy="0.000450453897318777"
        ixz="-0.000142032194705507"
        iyy="0.000793701521921683"
        iyz="0.000396980873965514"
        izz="0.00195281226208713" />
    </inertial>
    <visual>
      <origin
        xyz="0 0 0"
        rpy="0 0 0" />
      <geometry>
        <mesh
          filename="../meshes/Link_B2.STL" />
      </geometry>
      <material
        name="">
        <color
          rgba="1 1 1 1" />
      </material>
    </visual>
    <collision>
      <origin
        xyz="0 0 0"
        rpy="0 0 0" />
      <geometry>
        <mesh
          filename="../meshes/Link_B2.STL" />
      </geometry>
    </collision>
  </link>
  <joint
    name="joint_platform_B2"
    type="revolute">
    <origin
      xyz="0.0164025952708852 0.00137401341327159 0.102000000000029"
      rpy="0.0849621690785075 1.5707963267949 0" />
    <parent
      link="Link_B1" />
    <child
      link="Link_B2" />
    <axis
      xyz="0 0 1" />
    <limit
      lower="-2.26"
      upper="2.26"
      effort="100"
      velocity="50" />
  </joint>
  <link
    name="Link_B3">
    <inertial>
      <origin
        xyz="-0.0445835523044267 0.0396010749025043 0.00266699879920274"
        rpy="0 0 0" />
      <mass
        value="0.289639370938033" />
      <inertia
        ixx="0.000368538565038667"
        ixy="0.000238752155526786"
        ixz="0.000108127866575019"
        iyy="0.000425300259079389"
        iyz="-9.60150408414951E-05"
        izz="0.000614165810695594" />
    </inertial>
    <visual>
      <origin
        xyz="0 0 0"
        rpy="0 0 0" />
      <geometry>
        <mesh
          filename="../meshes/Link_B3.STL" />
      </geometry>
      <material
        name="">
        <color
          rgba="1 1 1 1" />
      </material>
    </visual>
    <collision>
      <origin
        xyz="0 0 0"
        rpy="0 0 0" />
      <geometry>
        <mesh
          filename="../meshes/Link_B3.STL" />
      </geometry>
    </collision>
  </link>
  <joint
    name="joint_platform_B3"
    type="revolute">
    <origin
      xyz="-0.0862037470031803 0.241063204199487 -0.00352514725905964"
      rpy="3.14159265358979 0 -0.0919224225404343" />
    <parent
      link="Link_B2" />
    <child
      link="Link_B3" />
    <axis
      xyz="0 0 1" />
    <limit
      lower="-2.26"
      upper="2.26"
      effort="100"
      velocity="50" />
  </joint>
  <link
    name="Link_B4">
    <inertial>
      <origin
        xyz="-0.00734522629106943 0.0164811078491696 -0.0599618100809589"
        rpy="0 0 0" />
      <mass
        value="0.239430613356858" />
      <inertia
        ixx="0.000282116069340483"
        ixy="8.61912197590685E-06"
        ixz="-1.79748327822411E-05"
        iyy="0.000266568837663139"
        iyz="4.04244202966505E-05"
        izz="0.000119899571670421" />
    </inertial>
    <visual>
      <origin
        xyz="0 0 0"
        rpy="0 0 0" />
      <geometry>
        <mesh
          filename="../meshes/Link_B4.STL" />
      </geometry>
      <material
        name="">
        <color
          rgba="1 1 1 1" />
      </material>
    </visual>
    <collision>
      <origin
        xyz="0 0 0"
        rpy="0 0 0" />
      <geometry>
        <mesh
          filename="../meshes/Link_B4.STL" />
      </geometry>
    </collision>
  </link>
  <joint
    name="joint_platform_B4"
    type="revolute">
    <origin
      xyz="-0.0960920462857941 0.0853717682345888 0.013226827485807"
      rpy="1.57079632679491 1.01854263840748 0.844439767031704" />
    <parent
      link="Link_B3" />
    <child
      link="Link_B4" />
    <axis
      xyz="0 0 1" />
    <limit
      lower="-3.14"
      upper="3.14"
      effort="100"
      velocity="50" />
  </joint>
  <link
    name="Link_B5">
    <inertial>
      <origin
        xyz="0.0113936142303117 0.0581872059745607 0.00506814468023165"
        rpy="0 0 0" />
      <mass
        value="0.218793325862955" />
      <inertia
        ixx="0.000341452617129859"
        ixy="-4.63203645787263E-05"
        ixz="-1.50283567730721E-05"
        iyy="0.000113994717660019"
        iyz="-7.67811785488284E-05"
        izz="0.000334463194187607" />
    </inertial>
    <visual>
      <origin
        xyz="0 0 0"
        rpy="0 0 0" />
      <geometry>
        <mesh
          filename="../meshes/Link_B5.STL" />
      </geometry>
      <material
        name="">
        <color
          rgba="1 1 1 1" />
      </material>
    </visual>
    <collision>
      <origin
        xyz="0 0 0"
        rpy="0 0 0" />
      <geometry>
        <mesh
          filename="../meshes/Link_B5.STL" />
      </geometry>
    </collision>
  </link>
  <joint
    name="joint_platform_B5"
    type="revolute">
    <origin
      xyz="0.00498093355069423 -0.0110668807595307 -0.0815561902327434"
      rpy="-1.5707963267949 -0.573741362025699 0.418364132516817" />
    <parent
      link="Link_B4" />
    <child
      link="Link_B5" />
    <axis
      xyz="0 0 1" />
    <limit
      lower="-2.2"
      upper="2.2"
      effort="100"
      velocity="50" />
  </joint>
  <link
    name="Link_B6">
    <inertial>
      <origin
        xyz="-0.00256296562750091 0.0162138395278224 0.10953897454242"
        rpy="0 0 0" />
      <mass
        value="0.652237455496743" />
      <inertia
        ixx="0.000319425998252991"
        ixy="1.39426400580414E-05"
        ixz="1.33570230674664E-08"
        iyy="0.000202680996434978"
        iyz="-3.08175467257231E-08"
        izz="0.000367350905559284" />
    </inertial>
    <visual>
      <origin
        xyz="0 0 0"
        rpy="0 0 0" />
      <geometry>
        <mesh
          filename="../meshes/Link_B6.STL" />
      </geometry>
      <material
        name="">
        <color
          rgba="1 1 1 1" />
      </material>
    </visual>
    <collision>
      <origin
        xyz="0 0 0"
        rpy="0 0 0" />
      <geometry>
        <mesh
          filename="../meshes/Link_B6.STL" />
      </geometry>
    </collision>
  </link>
  <joint
    name="joint_platform_B6"
    type="revolute">
    <origin
      xyz="0.0220769553081411 0.112769294031951 0.0124298510263973"
      rpy="-1.5707963267949 0.363602003221376 -0.193504212101692" />
    <parent
      link="Link_B5" />
    <child
      link="Link_B6" />
    <axis
      xyz="0 0 1" />
    <limit
      lower="-6.2"
      upper="6.2"
      effort="100"
      velocity="50" />
  </joint>
  <link
    name="Link_S1">
    <inertial>
      <origin
        xyz="-0.00111431623367674 -0.000394920204415866 -0.0279765574769409"
        rpy="0 0 0" />
      <mass
        value="0.106878620604356" />
      <inertia
        ixx="7.78786903515349E-05"
        ixy="-1.606819751846E-08"
        ixz="2.61075287396989E-06"
        iyy="9.22279471336507E-05"
        iyz="2.93084723436216E-07"
        izz="8.34708373040095E-05" />
    </inertial>
    <visual>
      <origin
        xyz="0 0 0"
        rpy="0 0 0" />
      <geometry>
        <mesh
          filename="../meshes/Link_S1.STL" />
      </geometry>
      <material
        name="">
        <color
          rgba="1 1 1 1" />
      </material>
    </visual>
    <collision>
      <origin
        xyz="0 0 0"
        rpy="0 0 0" />
      <geometry>
        <mesh
          filename="../meshes/Link_S1.STL" />
      </geometry>
    </collision>
  </link>
  <joint
    name="joint_platform_S1"
    type="revolute">
    <origin
      xyz="0.000433041860730524 0.000398644471470921 -0.39995"
      rpy="0 0 0" />
    <parent
      link="platform_link" />
    <child
      link="Link_S1" />
    <axis
      xyz="0 0 1" />
    <limit
      lower="-2.68"
      upper="2.68"
      effort="100"
      velocity="50" />
  </joint>
  <link
    name="Link_S2">
    <inertial>
      <origin
        xyz="0.0724194778767879 -0.131936188075807 0.044406043154082"
        rpy="0 0 0" />
      <mass
        value="0.203920919386394" />
      <inertia
        ixx="0.00128889812936827"
        ixy="0.00066263638005062"
        ixz="-7.91150391912721E-06"
        iyy="0.000642111780427922"
        iyz="3.8314689659501E-07"
        izz="0.00162755121218312" />
    </inertial>
    <visual>
      <origin
        xyz="0 0 0"
        rpy="0 0 0" />
      <geometry>
        <mesh
          filename="../meshes/Link_S2.STL" />
      </geometry>
      <material
        name="">
        <color
          rgba="1 1 1 1" />
      </material>
    </visual>
    <collision>
      <origin
        xyz="0 0 0"
        rpy="0 0 0" />
      <geometry>
        <mesh
          filename="../meshes/Link_S2.STL" />
      </geometry>
    </collision>
  </link>
  <joint
    name="joint_platform_S2"
    type="revolute">
    <origin
      xyz="0.0367444027969984 0.00064137593620528 -0.0370499999999101"
      rpy="1.5707963267949 0 -1.5533430342851" />
    <parent
      link="Link_S1" />
    <child
      link="Link_S2" />
    <axis
      xyz="0 0 1" />
    <limit
      lower="0"
      upper="3.3"
      effort="100"
      velocity="50" />
  </joint>
  <link
    name="Link_S3">
    <inertial>
      <origin
        xyz="0.100943213162187 -0.0283683578342203 0.0476334565574921"
        rpy="0 0 0" />
      <mass
        value="0.259290582671513" />
      <inertia
        ixx="9.87188428452086E-05"
        ixy="1.87582848560715E-05"
        ixz="-9.74231758607961E-07"
        iyy="0.00018114878198025"
        iyz="6.25962927670275E-07"
        izz="0.000209231319367455" />
    </inertial>
    <visual>
      <origin
        xyz="0 0 0"
        rpy="0 0 0" />
      <geometry>
        <mesh
          filename="../meshes/Link_S3.STL" />
      </geometry>
      <material
        name="">
        <color
          rgba="1 1 1 1" />
      </material>
    </visual>
    <collision>
      <origin
        xyz="0 0 0"
        rpy="0 0 0" />
      <geometry>
        <mesh
          filename="../meshes/Link_S3.STL" />
      </geometry>
    </collision>
  </link>
  <joint
    name="joint_platform_S3"
    type="revolute">
    <origin
      xyz="0.162822697705282 -0.233968487158141 -0.0104499999999984"
      rpy="0 0 0" />
    <parent
      link="Link_S2" />
    <child
      link="Link_S3" />
    <axis
      xyz="0 0 1" />
    <limit
      lower="0"
      upper="3.14"
      effort="100"
      velocity="50" />
  </joint>
  <link
    name="Link_S4">
    <inertial>
      <origin
        xyz="0.00107591854177631 -0.00020414949966685 0.0322093232185801"
        rpy="0 0 0" />
      <mass
        value="0.120706963097644" />
      <inertia
        ixx="4.59016732865594E-05"
        ixy="2.29836774590002E-08"
        ixz="6.8387688147042E-08"
        iyy="3.66186704128841E-05"
        iyz="-4.6682059016054E-08"
        izz="3.90050008398091E-05" />
    </inertial>
    <visual>
      <origin
        xyz="0 0 0"
        rpy="0 0 0" />
      <geometry>
        <mesh
          filename="../meshes/Link_S4.STL" />
      </geometry>
      <material
        name="">
        <color
          rgba="1 1 1 1" />
      </material>
    </visual>
    <collision>
      <origin
        xyz="0 0 0"
        rpy="0 0 0" />
      <geometry>
        <mesh
          filename="../meshes/Link_S4.STL" />
      </geometry>
    </collision>
  </link>
  <joint
    name="joint_platform_S4"
    type="revolute">
    <origin
      xyz="0.210129289624401 -0.0494636890451812 0.047199999999998"
      rpy="1.57079632679571 1.56854804510877 1.44163329792559" />
    <parent
      link="Link_S3" />
    <child
      link="Link_S4" />
    <axis
      xyz="0 0 -1" />
    <limit
      lower="-1.55"
      upper="1.55"
      effort="100"
      velocity="50" />
  </joint>
  <link
    name="Link_S5">
    <inertial>
      <origin
        xyz="3.87467427749866E-05 -0.0573118425040661 -0.0211795550061192"
        rpy="0 0 0" />
      <mass
        value="0.136459782082442" />
      <inertia
        ixx="0.000120530792445934"
        ixy="-2.73115643611787E-07"
        ixz="4.64606803997837E-08"
        iyy="6.56085938663145E-05"
        iyz="-2.43325821388101E-05"
        izz="0.000114402970292959" />
    </inertial>
    <visual>
      <origin
        xyz="0 0 0"
        rpy="0 0 0" />
      <geometry>
        <mesh
          filename="../meshes/Link_S5.STL" />
      </geometry>
      <material
        name="">
        <color
          rgba="1 1 1 1" />
      </material>
    </visual>
    <collision>
      <origin
        xyz="0 0 0"
        rpy="0 0 0" />
      <geometry>
        <mesh
          filename="../meshes/Link_S5.STL" />
      </geometry>
    </collision>
  </link>
  <joint
    name="joint_platform_S5"
    type="revolute">
    <origin
      xyz="0.0239199395449672 -5.37788526262517E-05 0.0369999999999999"
      rpy="1.57079632679489 -1.4416332979245 1.56854804510879" />
    <parent
      link="Link_S4" />
    <child
      link="Link_S5" />
    <axis
      xyz="0 0 -1" />
    <limit
      lower="-1.55"
      upper="1.55"
      effort="100"
      velocity="50" />
  </joint>
  <link
    name="Link_S6">
    <inertial>
      <origin
        xyz="0.000874537945305703 -0.0417696009854715 0.0121227762062894"
        rpy="0 0 0" />
      <mass
        value="0.319123227352636" />
      <inertia
        ixx="0.000210288101823833"
        ixy="5.15584728878731E-09"
        ixz="6.73512736976063E-07"
        iyy="0.000226598974932404"
        iyz="-2.80611253853446E-07"
        izz="0.000419233743639763" />
    </inertial>
    <visual>
      <origin
        xyz="0 0 0"
        rpy="0 0 0" />
      <geometry>
        <mesh
          filename="../meshes/Link_S6.STL" />
      </geometry>
      <material
        name="">
        <color
          rgba="0.898039215686275 0.917647058823529 0.929411764705882 1" />
      </material>
    </visual>
    <collision>
      <origin
        xyz="0 0 0"
        rpy="0 0 0" />
      <geometry>
        <mesh
          filename="../meshes/Link_S6.STL" />
      </geometry>
    </collision>
  </link>
  <joint
    name="joint_platform_S6"
    type="revolute">
    <origin
      xyz="0 -0.0909999999999964 -0.0249165214861997"
      rpy="1.57079632679511 -1.55334303428509 0" />
    <parent
      link="Link_S5" />
    <child
      link="Link_S6" />
    <axis
      xyz="0 0 -1" />
    <limit
      lower="-3"
      upper="3"
      effort="100"
      velocity="50" />
  </joint>
</robot>