<?xml version="1.0" encoding="utf-8"?>
<!-- This URDF was automatically created by SolidWorks to URDF Exporter! Originally created by Stephen Brawner (brawner@gmail.com) 
     Commit Version: 1.6.0-4-g7f85cfe  Build Version: 1.6.7995.38578
     For more information, please see http://wiki.ros.org/sw_urdf_exporter -->
<robot
  name="robot_V10">
  <!-- 虚拟世界link用于坐标系转换 -->
  <link name="world"/>
  <joint name="world_to_base" type="fixed">
    <parent link="world"/>
    <child link="base_link"/>
    <origin xyz="0 0 0" rpy="3.14159 0 0"/>
  </joint>
  <link
    name="base_link">
    <inertial>
      <origin
        xyz="0.035023 -0.045654 0.26704"
        rpy="0 0 0" />
      <mass
        value="289.28" />
      <inertia
        ixx="9.2366"
        ixy="0.0048895"
        ixz="0.0033066"
        iyy="19.365"
        iyz="0.51362"
        izz="22.329" />
    </inertial>
    <visual>
      <origin
        xyz="0 0 0"
        rpy="0 0 0" />
      <geometry>
        <mesh
          filename="../meshes/base_link.STL" />
      </geometry>
      <material
        name="">
        <color
          rgba="0.79216 0.81961 0.93333 1" />
      </material>
    </visual>
    <collision>
      <origin
        xyz="0 0 0"
        rpy="0 0 0" />
      <geometry>
        <mesh
          filename="../meshes/base_link.STL" />
      </geometry>
    </collision>
  </link>
  <link
    name="platform_link">
    <inertial>
      <origin
        xyz="0.0066954 0.032739 -0.19754"
        rpy="0 0 0" />
      <mass
        value="5.6268" />
      <inertia
        ixx="0.032913"
        ixy="-0.0010198"
        ixz="-7.8232E-06"
        iyy="0.033081"
        iyz="-5.0652E-05"
        izz="0.011116" />
    </inertial>
    <visual>
      <origin
        xyz="0 0 0"
        rpy="0 0 0" />
      <geometry>
        <mesh
          filename="../meshes/platform_link.STL" />
      </geometry>
      <material
        name="">
        <color
          rgba="0.89804 0.91765 0.92941 1" />
      </material>
    </visual>
    <collision>
      <origin
        xyz="0 0 0"
        rpy="0 0 0" />
      <geometry>
        <mesh
          filename="../meshes/platform_link.STL" />
      </geometry>
    </collision>
  </link>
  <joint
    name="joint_platform_D1"
    type="revolute">
    <origin
      xyz="0 0 0"
      rpy="0 0 0" />
    <parent
      link="base_link" />
    <child
      link="platform_link" />
    <axis
      xyz="0 0 -1" />
    <limit
      lower="-3.14"
      upper="3.14"
      effort="100"
      velocity="50" />
  </joint>
  <link
    name="Link_A1">
    <inertial>
      <origin
        xyz="0.0169308367894223 0.0125928013215484 0.0768128774242119"
        rpy="0 0 0" />
      <mass
        value="0.593525762282562" />
      <inertia
        ixx="0.001211740353914"
        ixy="-4.04510751675718E-05"
        ixz="-0.000169403894082202"
        iyy="0.00123597531032555"
        iyz="-0.000126111277061559"
        izz="0.000561310092473764" />
    </inertial>
    <visual>
      <origin
        xyz="0 0 0"
        rpy="0 0 0" />
      <geometry>
        <mesh
          filename="../meshes/Link_A1.STL" />
      </geometry>
      <material
        name="">
        <color
          rgba="1 1 1 1" />
      </material>
    </visual>
    <collision>
      <origin
        xyz="0 0 0"
        rpy="0 0 0" />
      <geometry>
        <mesh
          filename="../meshes/Link_A1.STL" />
      </geometry>
    </collision>
  </link>
  <joint
    name="joint_platform_A1"
    type="revolute">
    <origin
      xyz="0.15647 0.14243 -0.22731"
      rpy="-1.5708 0 -0.82673" />
    <parent
      link="platform_link" />
    <child
      link="Link_A1" />
    <axis
      xyz="0 0 1" />
    <limit
      lower="-3.14"
      upper="3.14"
      effort="100"
      velocity="50" />
  </joint>
  <link
    name="Link_A2">
    <inertial>
      <origin
        xyz="-0.0126344741233757 -0.151722416518289 0.0226638907321563"
        rpy="0 0 0" />
      <mass
        value="0.864181213916929" />
      <inertia
        ixx="0.00204291567607871"
        ixy="-0.000117497024088253"
        ixz="3.49972416744257E-05"
        iyy="0.000642323007807197"
        iyz="0.000420166237031602"
        izz="0.00195279764142988" />
    </inertial>
    <visual>
      <origin
        xyz="0 0 0"
        rpy="0 0 0" />
      <geometry>
        <mesh
          filename="../meshes/Link_A2.STL" />
      </geometry>
      <material
        name="">
        <color
          rgba="1 1 1 1" />
      </material>
    </visual>
    <collision>
      <origin
        xyz="0 0 0"
        rpy="0 0 0" />
      <geometry>
        <mesh
          filename="../meshes/Link_A2.STL" />
      </geometry>
    </collision>
  </link>
  <joint
    name="joint_platform_A2"
    type="revolute">
    <origin
      xyz="-0.0132108472999706 -0.00983204731723247 0.101999999998849"
      rpy="-1.5707963267949 -1.06818707313174 -0.930882582622158" />
    <parent
      link="Link_A1" />
    <child
      link="Link_A2" />
    <axis
      xyz="0 0 1" />
    <limit
      lower="-2.26"
      upper="2.26"
      effort="100"
      velocity="50" />
  </joint>
  <link
    name="Link_A3">
    <inertial>
      <origin
        xyz="-0.117800833591657 -0.0232736791268702 0.0441646444842317"
        rpy="0 0 0" />
      <mass
        value="0.289645631614414" />
      <inertia
        ixx="0.000618421627917276"
        ixy="-2.18347022998156E-05"
        ixz="9.7003656600718E-05"
        iyy="0.000621846882953289"
        iyz="0.000127897601239021"
        izz="0.000167775261531985" />
    </inertial>
    <visual>
      <origin
        xyz="0 0 0"
        rpy="0 0 0" />
      <geometry>
        <mesh
          filename="../meshes/Link_A3.STL" />
      </geometry>
      <material
        name="">
        <color
          rgba="1 1 1 1" />
      </material>
    </visual>
    <collision>
      <origin
        xyz="0 0 0"
        rpy="0 0 0" />
      <geometry>
        <mesh
          filename="../meshes/Link_A3.STL" />
      </geometry>
    </collision>
  </link>
  <joint
    name="joint_platform_A3"
    type="revolute">
    <origin
      xyz="-0.012678652632737 -0.151961786830407 0.0164610793638682"
      rpy="1.00030254860532 -0.123402688706427 1.56650766817711" />
    <parent
      link="Link_A2" />
    <child
      link="Link_A3" />
    <axis
      xyz="0 0 -1" />
    <limit
      lower="-2.26"
      upper="2.26"
      effort="100"
      velocity="50" />
  </joint>
  <link
    name="Link_A4">
    <inertial>
      <origin
        xyz="0.016896007871893 -0.00633304037762816 -0.05996151419747"
        rpy="0 0 0" />
      <mass
        value="0.239433776027785" />
      <inertia
        ixx="0.000265607043125794"
        ixy="7.64305481199854E-06"
        ixz="4.14131935380001E-05"
        iyy="0.000283077940585531"
        iyz="-1.55624791539585E-05"
        izz="0.000119899346983553" />
    </inertial>
    <visual>
      <origin
        xyz="0 0 0"
        rpy="0 0 0" />
      <geometry>
        <mesh
          filename="../meshes/Link_A4.STL" />
      </geometry>
      <material
        name="">
        <color
          rgba="1 1 1 1" />
      </material>
    </visual>
    <collision>
      <origin
        xyz="0 0 0"
        rpy="0 0 0" />
      <geometry>
        <mesh
          filename="../meshes/Link_A4.STL" />
      </geometry>
    </collision>
  </link>
  <joint
    name="joint_platform_A4"
    type="revolute">
    <origin
      xyz="-0.132857488365902 -0.0488711328328308 0.107236171903331"
      rpy="-3.06893016634827 -0.582064137953246 0.995874517388692" />
    <parent
      link="Link_A3" />
    <child
      link="Link_A4" />
    <axis
      xyz="0 0 -1" />
    <limit
      lower="-3.14"
      upper="3.14"
      effort="100"
      velocity="50" />
  </joint>
  <link
    name="Link_A5">
    <inertial>
      <origin
        xyz="0.0380094230376776 0.0456440434886026 0.00506810747745645"
        rpy="0 0 0" />
      <mass
        value="0.218793807603732" />
      <inertia
        ixx="0.000249967614137682"
        ixy="-0.000120769356677445"
        ixz="-5.00570691133891E-05"
        iyy="0.000205481998419059"
        iyz="-6.01294670291514E-05"
        izz="0.000334465752993695" />
    </inertial>
    <visual>
      <origin
        xyz="0 0 0"
        rpy="0 0 0" />
      <geometry>
        <mesh
          filename="../meshes/Link_A5.STL" />
      </geometry>
      <material
        name="">
        <color
          rgba="1 1 1 1" />
      </material>
    </visual>
    <collision>
      <origin
        xyz="0 0 0"
        rpy="0 0 0" />
      <geometry>
        <mesh
          filename="../meshes/Link_A5.STL" />
      </geometry>
    </collision>
  </link>
  <joint
    name="joint_platform_A5"
    type="revolute">
    <origin
      xyz="-0.0113606247812901 0.0042683371510126 -0.0814999999999998"
      rpy="1.5707963267949 1.32513220794321 1.21130110529" />
    <parent
      link="Link_A4" />
    <child
      link="Link_A5" />
    <axis
      xyz="0 0 1" />
    <limit
      lower="-2.2"
      upper="2.2"
      effort="100"
      velocity="50" />
  </joint>
  <link
    name="Link_A6">
    <inertial>
      <origin
        xyz="0.00606884565213639 0.0152502416830383 0.109538960794972"
        rpy="0 0 0" />
      <mass
        value="0.652237451823604" />
      <inertia
        ixx="0.000301203372093203"
        ixy="-4.46063215910981E-05"
        ixz="-4.21673354066232E-09"
        iyy="0.000220903467434786"
        iyz="-3.3358058851477E-08"
        izz="0.000367350798134239" />
    </inertial>
    <visual>
      <origin
        xyz="0 0 0"
        rpy="0 0 0" />
      <geometry>
        <mesh
          filename="../meshes/Link_A6.STL" />
      </geometry>
      <material
        name="">
        <color
          rgba="1 1 1 1" />
      </material>
    </visual>
    <collision>
      <origin
        xyz="0 0 0"
        rpy="0 0 0" />
      <geometry>
        <mesh
          filename="../meshes/Link_A6.STL" />
      </geometry>
    </collision>
  </link>
  <joint
    name="joint_platform_A6"
    type="revolute">
    <origin
      xyz="0.0736102642149934 0.0883749191141996 0.0124357145512975"
      rpy="-1.57079646161027 -0.699913541621339 -0.694444981452453" />
    <parent
      link="Link_A5" />
    <child
      link="Link_A6" />
    <axis
      xyz="0 0 0.999999999999972" />
    <limit
      lower="-6.2"
      upper="6.2"
      effort="100"
      velocity="50" />
  </joint>
  <link
    name="Link_B1">
    <inertial>
      <origin
        xyz="-0.0210307676752361 -0.00180296761393567 0.0768121489222187"
        rpy="0 0 0" />
      <mass
        value="0.593520652882471" />
      <inertia
        ixx="0.0011822089514045"
        ixy="-7.13362620080486E-06"
        ixz="0.00021041828482838"
        iyy="0.00126545347768904"
        iyz="1.79134043694063E-05"
        izz="0.000561301130529158" />
    </inertial>
    <visual>
      <origin
        xyz="0 0 0"
        rpy="0 0 0" />
      <geometry>
        <mesh
          filename="../meshes/Link_B1.STL" />
      </geometry>
      <material
        name="">
        <color
          rgba="1 1 1 1" />
      </material>
    </visual>
    <collision>
      <origin
        xyz="0 0 0"
        rpy="0 0 0" />
      <geometry>
        <mesh
          filename="../meshes/Link_B1.STL" />
      </geometry>
    </collision>
  </link>
  <joint
    name="joint_platform_B1"
    type="revolute">
    <origin
      xyz="-0.142473632839857 0.155636147433961 -0.227311716711636"
      rpy="-1.57079632679501 0 0.744063112694143" />
    <parent
      link="platform_link" />
    <child
      link="Link_B1" />
    <axis
      xyz="0 0 1" />
    <limit
      lower="-3.1"
      upper="3.1"
      effort="100"
      velocity="50" />
  </joint>
  <link
    name="Link_B2">
    <inertial>
      <origin
        xyz="-0.153292355655283 0.143345908217216 -0.00620379121866188"
        rpy="0 0 0" />
      <mass
        value="0.864180134866302" />
      <inertia
        ixx="0.0018915534289376"
        ixy="0.000450453898027771"
        ixz="-0.000142032194786381"
        iyy="0.000793701521401255"
        iyz="0.000396980873495538"
        izz="0.00195281225823474" />
    </inertial>
    <visual>
      <origin
        xyz="0 0 0"
        rpy="0 0 0" />
      <geometry>
        <mesh
          filename="../meshes/Link_B2.STL" />
      </geometry>
      <material
        name="">
        <color
          rgba="1 1 1 1" />
      </material>
    </visual>
    <collision>
      <origin
        xyz="0 0 0"
        rpy="0 0 0" />
      <geometry>
        <mesh
          filename="../meshes/Link_B2.STL" />
      </geometry>
    </collision>
  </link>
  <joint
    name="joint_platform_B2"
    type="revolute">
    <origin
      xyz="0 0 0"
      rpy="0.0849621690785075 1.5707963267949 0" />
    <parent
      link="Link_B1" />
    <child
      link="Link_B2" />
    <axis
      xyz="0 0 1" />
    <limit
      lower="-2.26"
      upper="2.26"
      effort="100"
      velocity="50" />
  </joint>
  <link
    name="Link_B3">
    <inertial>
      <origin
        xyz="-0.0445835523125042 0.0396010749080349 0.00266699880015819"
        rpy="0 0 0" />
      <mass
        value="0.289639370831344" />
      <inertia
        ixx="0.00036853856501621"
        ixy="0.000238752155491364"
        ixz="0.000108127866568749"
        iyy="0.000425300259027599"
        iyz="-9.60150408361627E-05"
        izz="0.000614165810618468" />
    </inertial>
    <visual>
      <origin
        xyz="0 0 0"
        rpy="0 0 0" />
      <geometry>
        <mesh
          filename="../meshes/Link_B3.STL" />
      </geometry>
      <material
        name="">
        <color
          rgba="1 1 1 1" />
      </material>
    </visual>
    <collision>
      <origin
        xyz="0 0 0"
        rpy="0 0 0" />
      <geometry>
        <mesh
          filename="../meshes/Link_B3.STL" />
      </geometry>
    </collision>
  </link>
  <joint
    name="joint_platform_B3"
    type="revolute">
    <origin
      xyz="-0.188203747003209 0.241040337344676 0.0129348807356726"
      rpy="3.14159265358979 0 -0.0919224225404343" />
    <parent
      link="Link_B2" />
    <child
      link="Link_B3" />
    <axis
      xyz="0 0 1" />
    <limit
      lower="-2.26"
      upper="2.26"
      effort="100"
      velocity="50" />
  </joint>
  <link
    name="Link_B4">
    <inertial>
      <origin
        xyz="-0.00734522628431628 0.0164811077834319 -0.0599618100191497"
        rpy="0 0 0" />
      <mass
        value="0.239430613748721" />
      <inertia
        ixx="0.000282116070585354"
        ixy="8.61912204153082E-06"
        ixz="-1.79748328384806E-05"
        iyy="0.00026656883823886"
        iyz="4.04244209097807E-05"
        izz="0.000119899572352226" />
    </inertial>
    <visual>
      <origin
        xyz="0 0 0"
        rpy="0 0 0" />
      <geometry>
        <mesh
          filename="../meshes/Link_B4.STL" />
      </geometry>
      <material
        name="">
        <color
          rgba="1 1 1 1" />
      </material>
    </visual>
    <collision>
      <origin
        xyz="0 0 0"
        rpy="0 0 0" />
      <geometry>
        <mesh
          filename="../meshes/Link_B4.STL" />
      </geometry>
    </collision>
  </link>
  <joint
    name="joint_platform_B4"
    type="revolute">
    <origin
      xyz="-0.0960920462857941 0.0853717682345888 0.013226827485807"
      rpy="1.57079632679491 1.01854263840748 0.844439767031704" />
    <parent
      link="Link_B3" />
    <child
      link="Link_B4" />
    <axis
      xyz="0 0 1" />
    <limit
      lower="-3.14"
      upper="3.14"
      effort="100"
      velocity="50" />
  </joint>
  <link
    name="Link_B5">
    <inertial>
      <origin
        xyz="0.011393611132646 0.0581872049826706 0.00506814258546151"
        rpy="0 0 0" />
      <mass
        value="0.218793290035851" />
      <inertia
        ixx="0.000341452617618079"
        ixy="-4.63203639628417E-05"
        ixz="-1.50283512281207E-05"
        iyy="0.000113994705208513"
        iyz="-7.67811787013923E-05"
        izz="0.000334463186991967" />
    </inertial>
    <visual>
      <origin
        xyz="0 0 0"
        rpy="0 0 0" />
      <geometry>
        <mesh
          filename="../meshes/Link_B5.STL" />
      </geometry>
      <material
        name="">
        <color
          rgba="1 1 1 1" />
      </material>
    </visual>
    <collision>
      <origin
        xyz="0 0 0"
        rpy="0 0 0" />
      <geometry>
        <mesh
          filename="../meshes/Link_B5.STL" />
      </geometry>
    </collision>
  </link>
  <joint
    name="joint_platform_B5"
    type="revolute">
    <origin
      xyz="0.00498093355069423 -0.0110668807595307 -0.0815561902327434"
      rpy="-1.5707963267949 -0.573741362025699 0.418364132516817" />
    <parent
      link="Link_B4" />
    <child
      link="Link_B5" />
    <axis
      xyz="0 0 1" />
    <limit
      lower="-2.2"
      upper="2.2"
      effort="100"
      velocity="50" />
  </joint>
  <link
    name="Link_B6">
    <inertial>
      <origin
        xyz="-0.00256296562750091 0.0162138395278226 0.10953897454242"
        rpy="0 0 0" />
      <mass
        value="0.652237455496744" />
      <inertia
        ixx="0.000319425998252991"
        ixy="1.39426400580414E-05"
        ixz="1.33570230674588E-08"
        iyy="0.000202680996434978"
        iyz="-3.08175467257502E-08"
        izz="0.000367350905559284" />
    </inertial>
    <visual>
      <origin
        xyz="0 0 0"
        rpy="0 0 0" />
      <geometry>
        <mesh
          filename="../meshes/Link_B6.STL" />
      </geometry>
      <material
        name="">
        <color
          rgba="1 1 1 1" />
      </material>
    </visual>
    <collision>
      <origin
        xyz="0 0 0"
        rpy="0 0 0" />
      <geometry>
        <mesh
          filename="../meshes/Link_B6.STL" />
      </geometry>
    </collision>
  </link>
  <joint
    name="joint_platform_B6"
    type="revolute">
    <origin
      xyz="0.0220769553081411 0.112769294031951 0.0124298510263973"
      rpy="-1.5707963267949 0.363602003221376 -0.193504212101692" />
    <parent
      link="Link_B5" />
    <child
      link="Link_B6" />
    <axis
      xyz="0 0 1" />
    <limit
      lower="-6.2"
      upper="6.2"
      effort="100"
      velocity="50" />
  </joint>
  <link
    name="Link_S1">
    <inertial>
      <origin
        xyz="-0.00111431623367673 -0.000394920204415852 -0.0279765574769409"
        rpy="0 0 0" />
      <mass
        value="0.106878620604356" />
      <inertia
        ixx="7.78786903515349E-05"
        ixy="-1.60681975184557E-08"
        ixz="2.61075287396989E-06"
        iyy="9.22279471336507E-05"
        iyz="2.93084723436216E-07"
        izz="8.34708373040095E-05" />
    </inertial>
    <visual>
      <origin
        xyz="0 0 0"
        rpy="0 0 0" />
      <geometry>
        <mesh
          filename="../meshes/Link_S1.STL" />
      </geometry>
      <material
        name="">
        <color
          rgba="1 1 1 1" />
      </material>
    </visual>
    <collision>
      <origin
        xyz="0 0 0"
        rpy="0 0 0" />
      <geometry>
        <mesh
          filename="../meshes/Link_S1.STL" />
      </geometry>
    </collision>
  </link>
  <joint
    name="joint_platform_S1"
    type="revolute">
    <origin
      xyz="0.000433041860730524 0.000398644471470921 -0.39995"
      rpy="0 0 0" />
    <parent
      link="platform_link" />
    <child
      link="Link_S1" />
    <axis
      xyz="0 0 1" />
    <limit
      lower="-2.68"
      upper="2.68"
      effort="100"
      velocity="50" />
  </joint>
  <link
    name="Link_S2">
    <inertial>
      <origin
        xyz="0.0724194778767879 -0.131936188075807 0.044406043154082"
        rpy="0 0 0" />
      <mass
        value="0.203920919386394" />
      <inertia
        ixx="0.00128889812936827"
        ixy="0.00066263638005062"
        ixz="-7.91150391912717E-06"
        iyy="0.000642111780427921"
        iyz="3.83146896595018E-07"
        izz="0.00162755121218312" />
    </inertial>
    <visual>
      <origin
        xyz="0 0 0"
        rpy="0 0 0" />
      <geometry>
        <mesh
          filename="../meshes/Link_S2.STL" />
      </geometry>
      <material
        name="">
        <color
          rgba="1 1 1 1" />
      </material>
    </visual>
    <collision>
      <origin
        xyz="0 0 0"
        rpy="0 0 0" />
      <geometry>
        <mesh
          filename="../meshes/Link_S2.STL" />
      </geometry>
    </collision>
  </link>
  <joint
    name="joint_platform_S2"
    type="revolute">
    <origin
      xyz="0.0367444027969984 0.00064137593620528 -0.0370499999999101"
      rpy="1.5707963267949 0 -1.5533430342851" />
    <parent
      link="Link_S1" />
    <child
      link="Link_S2" />
    <axis
      xyz="0 0 1" />
    <limit
      lower="0"
      upper="3.3"
      effort="100"
      velocity="50" />
  </joint>
  <link
    name="Link_S3">
    <inertial>
      <origin
        xyz="0.100943213162187 -0.0283683578342204 0.0476334565574921"
        rpy="0 0 0" />
      <mass
        value="0.259290582671513" />
      <inertia
        ixx="9.87188428452086E-05"
        ixy="1.87582848560715E-05"
        ixz="-9.74231758607965E-07"
        iyy="0.00018114878198025"
        iyz="6.25962927670277E-07"
        izz="0.000209231319367455" />
    </inertial>
    <visual>
      <origin
        xyz="0 0 0"
        rpy="0 0 0" />
      <geometry>
        <mesh
          filename="../meshes/Link_S3.STL" />
      </geometry>
      <material
        name="">
        <color
          rgba="1 1 1 1" />
      </material>
    </visual>
    <collision>
      <origin
        xyz="0 0 0"
        rpy="0 0 0" />
      <geometry>
        <mesh
          filename="../meshes/Link_S3.STL" />
      </geometry>
    </collision>
  </link>
  <joint
    name="joint_platform_S3"
    type="revolute">
    <origin
      xyz="0.162822697705282 -0.233968487158141 -0.0104499999999984"
      rpy="0 0 0" />
    <parent
      link="Link_S2" />
    <child
      link="Link_S3" />
    <axis
      xyz="0 0 1" />
    <limit
      lower="0"
      upper="3.14"
      effort="100"
      velocity="50" />
  </joint>
  <link
    name="Link_S4">
    <inertial>
      <origin
        xyz="0.00107591847887858 -0.000204149584096758 0.0322093232186499"
        rpy="0 0 0" />
      <mass
        value="0.120706963487323" />
      <inertia
        ixx="4.5901673414908E-05"
        ixy="2.29837753182355E-08"
        ixz="6.83876857454174E-08"
        iyy="3.66186703730379E-05"
        iyz="-4.6682057318395E-08"
        izz="3.90050010786891E-05" />
    </inertial>
    <visual>
      <origin
        xyz="0 0 0"
        rpy="0 0 0" />
      <geometry>
        <mesh
          filename="../meshes/Link_S4.STL" />
      </geometry>
      <material
        name="">
        <color
          rgba="1 1 1 1" />
      </material>
    </visual>
    <collision>
      <origin
        xyz="0 0 0"
        rpy="0 0 0" />
      <geometry>
        <mesh
          filename="../meshes/Link_S4.STL" />
      </geometry>
    </collision>
  </link>
  <joint
    name="joint_platform_S4"
    type="revolute">
    <origin
      xyz="0.210129289624401 -0.0494636890451812 0.047199999999998"
      rpy="1.57079632679571 1.56854804510877 1.44163329792559" />
    <parent
      link="Link_S3" />
    <child
      link="Link_S4" />
    <axis
      xyz="0 0 -1" />
    <limit
      lower="-1.55"
      upper="1.55"
      effort="100"
      velocity="50" />
  </joint>
  <link
    name="Link_S5">
    <inertial>
      <origin
        xyz="3.8721804861086E-05 -0.0573117732132232 -0.0211795210257932"
        rpy="0 0 0" />
      <mass
        value="0.136460063146015" />
      <inertia
        ixx="0.000120531193470609"
        ixy="-2.72999966574502E-07"
        ixz="4.65203886805748E-08"
        iyy="6.56087192754961E-05"
        iyz="-2.43327385970916E-05"
        izz="0.000114403333603092" />
    </inertial>
    <visual>
      <origin
        xyz="0 0 0"
        rpy="0 0 0" />
      <geometry>
        <mesh
          filename="../meshes/Link_S5.STL" />
      </geometry>
      <material
        name="">
        <color
          rgba="1 1 1 1" />
      </material>
    </visual>
    <collision>
      <origin
        xyz="0 0 0"
        rpy="0 0 0" />
      <geometry>
        <mesh
          filename="../meshes/Link_S5.STL" />
      </geometry>
    </collision>
  </link>
  <joint
    name="joint_platform_S5"
    type="revolute">
    <origin
      xyz="0.0239199395449672 -5.37788526262517E-05 0.0369999999999999"
      rpy="1.57079632679489 -1.4416332979245 1.56854804510879" />
    <parent
      link="Link_S4" />
    <child
      link="Link_S5" />
    <axis
      xyz="0 0 -1" />
    <limit
      lower="-1.55"
      upper="1.55"
      effort="100"
      velocity="50" />
  </joint>
  <link
    name="Link_S6">
    <inertial>
      <origin
        xyz="0.000874537945095726 -0.0417696009857867 0.0121227762064126"
        rpy="0 0 0" />
      <mass
        value="0.31912322735761" />
      <inertia
        ixx="0.000210288101824317"
        ixy="5.1558478536918E-09"
        ixz="6.73512736582423E-07"
        iyy="0.000226598974933412"
        iyz="-2.8061125364473E-07"
        izz="0.000419233743641026" />
    </inertial>
    <visual>
      <origin
        xyz="0 0 0"
        rpy="0 0 0" />
      <geometry>
        <mesh
          filename="../meshes/Link_S6.STL" />
      </geometry>
      <material
        name="">
        <color
          rgba="0.898039215686275 0.917647058823529 0.929411764705882 1" />
      </material>
    </visual>
    <collision>
      <origin
        xyz="0 0 0"
        rpy="0 0 0" />
      <geometry>
        <mesh
          filename="../meshes/Link_S6.STL" />
      </geometry>
    </collision>
  </link>
  <joint
    name="joint_platform_S6"
    type="revolute">
    <origin
      xyz="0 -0.0909999999999964 -0.0249165214861997"
      rpy="1.57079632679511 -1.55334303428509 0" />
    <parent
      link="Link_S5" />
    <child
      link="Link_S6" />
    <axis
      xyz="0 0 -1" />
    <limit
      lower="-3"
      upper="3"
      effort="100"
      velocity="50" />
  </joint>
</robot>